<?xml version="1.0"?>
<!-- =================================================================================== -->
<!-- |    This document was autogenerated by xacro from panda_arm.urdf.xacro           | -->
<!-- |    EDITING THIS FILE BY HAND IS NOT RECOMMENDED                                 | -->
<!-- =================================================================================== -->
<robot name="panda">
    <link name="panda_link0">
        <visual>
            <geometry>
                <mesh filename="franka_description/meshes/visual/link0.glb" />
            </geometry>
        </visual>
        <collision>
            <geometry>
                <mesh filename="franka_description/meshes/collision/link0.stl" />
            </geometry>
        </collision>
        <inertial>
            <origin rpy="0 0 0" xyz="-0.041018 -0.00014 0.049974" />
            <mass value="0.629769" />
            <inertia ixx="0.00315" ixy="8.2904e-07" ixz="0.00015" iyy="0.00388" iyz="8.2299e-06"
                izz="0.004285" />
        </inertial>
    </link>
    <link name="panda_link1">
        <visual>
            <geometry>
                <mesh filename="franka_description/meshes/visual/link1.glb" />
            </geometry>
        </visual>
        <collision>
            <geometry>
                <mesh filename="franka_description/meshes/collision/link1.stl" />
            </geometry>
        </collision>
        <inertial>
            <origin rpy="0 0 0" xyz="0.003875 0.002081 -0.04762" />
            <mass value="4.970684" />
            <inertia ixx="0.70337" ixy="-0.000139" ixz="0.006772" iyy="0.70661" iyz="0.019169"
                izz="0.009117" />
        </inertial>
    </link>
    <joint name="panda_joint1" type="revolute">
        <safety_controller k_position="100.0" k_velocity="40.0" soft_lower_limit="-2.8973"
            soft_upper_limit="2.8973" />
        <origin rpy="0 0 0" xyz="0 0 0.333" />
        <parent link="panda_link0" />
        <child link="panda_link1" />
        <axis xyz="0 0 1" />
        <limit effort="87" lower="-1.5" upper="1.0" velocity="2.1750" />
        <dynamics D="1" K="7000" damping="0.003" friction="0.0" mu_coulomb="0" mu_viscous="16" />
    </joint>
    <link name="panda_link2">
        <visual>
            <geometry>
                <mesh filename="franka_description/meshes/visual/link2.glb" />
            </geometry>
        </visual>
        <collision>
            <geometry>
                <mesh filename="franka_description/meshes/collision/link2.stl" />
            </geometry>
        </collision>
        <inertial>
            <origin rpy="0 0 0" xyz="-0.003141 -0.02872  0.003495" />
            <mass value="0.646926" />
            <inertia ixx="0.007962" ixy="-0.003925" ixz="0.010254" iyy="0.02811" iyz="0.000704"
                izz="0.025995" />
        </inertial>
    </link>
    <joint name="panda_joint2" type="revolute">
        <safety_controller k_position="100.0" k_velocity="40.0" soft_lower_limit="-1.7628"
            soft_upper_limit="1.7628" />
        <origin rpy="-1.5707963267948966 0 0" xyz="0 0 0" />
        <parent link="panda_link1" />
        <child link="panda_link2" />
        <axis xyz="0 0 1" />
        <limit effort="87" lower="-1.0" upper="1.0" velocity="2.1750" />
        <dynamics D="1" K="7000" damping="0.003" friction="0.0" mu_coulomb="0" mu_viscous="16" />
    </joint>
    <link name="panda_link3">
        <visual>
            <geometry>
                <mesh filename="franka_description/meshes/visual/link3.glb" />
            </geometry>
        </visual>
        <collision>
            <geometry>
                <mesh filename="franka_description/meshes/collision/link3.stl" />
            </geometry>
        </collision>
        <inertial>
            <origin rpy="0 0 0" xyz="2.7518e-02 3.9252e-02 -6.6502e-02" />
            <mass value="3.228604" />
            <inertia ixx="0.037242" ixy="-0.004761" ixz="-0.011396" iyy="0.036155" iyz="-0.012805"
                izz="0.01083" />
        </inertial>
    </link>
    <joint name="panda_joint3" type="revolute">
        <safety_controller k_position="100.0" k_velocity="40.0" soft_lower_limit="-2.8973"
            soft_upper_limit="2.8973" />
        <origin rpy="1.5707963267948966 0 0" xyz="0 -0.316 0" />
        <parent link="panda_link2" />
        <child link="panda_link3" />
        <axis xyz="0 0 1" />
        <limit effort="87" lower="-2.0" upper="2.0" velocity="2.1750" />
        <dynamics D="1" K="7000" damping="0.003" friction="0.0" mu_coulomb="0" mu_viscous="16" />
    </joint>
    <link name="panda_link4">
        <visual>
            <geometry>
                <mesh filename="franka_description/meshes/visual/link4.glb" />
            </geometry>
        </visual>
        <collision>
            <geometry>
                <mesh filename="franka_description/meshes/collision/link4.stl" />
            </geometry>
        </collision>
        <inertial>
            <origin rpy="0 0 0" xyz="-5.317e-02 1.04419e-01 2.7454e-02" />
            <mass value="3.587895" />
            <inertia ixx="0.025853" ixy="0.007796" ixz="-0.001332" iyy="0.019552" iyz="0.008641"
                izz="0.028323" />
        </inertial>
    </link>
    <joint name="panda_joint4" type="revolute">
        <safety_controller k_position="100.0" k_velocity="40.0" soft_lower_limit="-3.0718"
            soft_upper_limit="-0.0698" />
        <origin rpy="1.5707963267948966 0 0" xyz="0.0825 0 0" />
        <parent link="panda_link3" />
        <child link="panda_link4" />
        <axis xyz="0 0 1" />
        <limit effort="87" lower="-3.0718" upper="-0.0698" velocity="2.1750" />
        <dynamics D="1" K="7000" damping="0.003" friction="0.0" mu_coulomb="0" mu_viscous="16" />
    </joint>
    <link name="panda_link5">
        <visual>
            <geometry>
                <mesh filename="franka_description/meshes/visual/link5.glb" />
            </geometry>
        </visual>
        <collision>
            <geometry>
                <mesh filename="franka_description/meshes/collision/link5.stl" />
            </geometry>
        </collision>
        <inertial>
            <origin rpy="0 0 0" xyz="-1.1953e-02 4.1065e-02 -3.8437e-02" />
            <mass value="1.225946" />
            <inertia ixx="0.035549" ixy="-0.002117" ixz="-0.004037" iyy="0.029474" iyz="0.000229"
                izz="0.008627" />
        </inertial>
    </link>
    <joint name="panda_joint5" type="revolute">
        <safety_controller k_position="100.0" k_velocity="40.0" soft_lower_limit="-2.8973"
            soft_upper_limit="2.8973" />
        <origin rpy="-1.5707963267948966 0 0" xyz="-0.0825 0.384 0" />
        <parent link="panda_link4" />
        <child link="panda_link5" />
        <axis xyz="0 0 1" />
        <limit effort="12" lower="-2.0" upper="2.0" velocity="2.6100" />
        <dynamics D="1" K="7000" damping="0.003" friction="0.0" mu_coulomb="0" mu_viscous="16" />
    </joint>
    <link name="panda_link6">
        <visual>
            <geometry>
                <mesh filename="franka_description/meshes/visual/link6.glb" />
            </geometry>
        </visual>
        <collision>
            <geometry>
                <mesh filename="franka_description/meshes/collision/link6.stl" />
            </geometry>
        </collision>
        <inertial>
            <origin rpy="0 0 0" xyz="6.0149e-02 -1.4117e-02 -1.0517e-02" />
            <mass value="1.666555" />
            <inertia ixx="0.001964" ixy="0.000109" ixz="-0.001158" iyy="0.004354" iyz="0.000341"
                izz="0.005433" />
        </inertial>
    </link>
    <joint name="panda_joint6" type="revolute">
        <safety_controller k_position="100.0" k_velocity="40.0" soft_lower_limit="-0.0175"
            soft_upper_limit="3.7525" />
        <origin rpy="1.5707963267948966 0 0" xyz="0 0 0" />
        <parent link="panda_link5" />
        <child link="panda_link6" />
        <axis xyz="0 0 1" />
        <limit effort="12" lower="-0.0175" upper="3.7525" velocity="2.6100" />
        <dynamics D="1" K="7000" damping="0.003" friction="0.0" mu_coulomb="0" mu_viscous="16" />
    </joint>
    <link name="panda_link7">
        <visual>
            <geometry>
                <mesh filename="franka_description/meshes/visual/link7.glb" />
            </geometry>
        </visual>
        <collision>
            <geometry>
                <mesh filename="franka_description/meshes/collision/link7.stl" />
            </geometry>
        </collision>
        <inertial>
            <origin rpy="0 0 0" xyz="1.0517e-02 -4.252e-03 6.1597e-02" />
            <mass value="0.735522" />
            <inertia ixx="0.012516" ixy="-0.000428" ixz="-0.001196" iyy="0.010027" iyz="-0.000741"
                izz="0.004815" />
        </inertial>
    </link>
    <joint name="panda_joint7" type="revolute">
        <safety_controller k_position="100.0" k_velocity="40.0" soft_lower_limit="-2.8973"
            soft_upper_limit="2.8973" />
        <origin rpy="1.5707963267948966 0 0" xyz="0.088 0 0" />
        <parent link="panda_link6" />
        <child link="panda_link7" />
        <axis xyz="0 0 1" />
        <limit effort="12" lower="-2.8973" upper="2.8973" velocity="2.6100" />
        <dynamics D="1" K="7000" damping="0.003" friction="0.0" mu_coulomb="0" mu_viscous="16" />
    </joint>

    <joint name="part_studio_joint" type="fixed">
        <parent link="panda_link7" />
        <child link="part_studio_link" />
        <origin rpy="0 0 3.141592" xyz="0 -0.02 0.107" />
    </joint>

    <link name="part_studio_link">
        <visual>
            <origin rpy="-1.571 0 0" />
            <geometry>
                <mesh filename="franka_description/meshes/visual/mount_v6.stl"
                    scale="0.001 0.001 0.001" />
            </geometry>
        </visual>
        <collision>
            <origin xyz="0 0 0.017" rpy="-1.571 0 0" />
            <geometry>
                <box size="0.05 0.034 0.065" />
            </geometry>
        </collision>
        <inertial>
            <origin xyz="0 0 0.017" rpy="-1.571 0 0" />
            <mass value="0.05" />
            <inertia ixx="2.24e-5" iyy="2.80e-5" izz="1.52e-5" ixy="0" ixz="0" iyz="0" />
        </inertial>
    </link>

    <joint name="panda_hand_joint" type="fixed">
        <parent link="part_studio_link" />
        <child link="base_link" />
        <origin rpy="0 -1.5707 -1.5707" xyz="0.00 0.12 0.025" />
    </joint>

    <link name="base_link">
        <inertial>
            <mass value="0.4154" />
            <origin rpy="0 0 0" xyz="0 0 0" />
            <inertia ixx="1e-4" ixy="0" ixz="0" iyy="1e-4" iyz="0" izz="1e-4" />
        </inertial>
        <visual>
            <geometry>
                <mesh filename="meshes/visual/base_link.obj" />
            </geometry>
            <origin rpy="0 0 0" xyz="0 0 0 " />
        </visual>
        <collision>
            <origin rpy="0 0 0" xyz="-0.009 0.0 -0.023" />
            <geometry>
                <box size="0.0414 0.112 0.0448" />
            </geometry>
        </collision>
        <collision>
            <origin rpy="0 0 0" xyz="-0.009 -0.0253 -0.0667" />
            <geometry>
                <box size="0.0414 0.0538 0.0428" />
            </geometry>
        </collision>
        <collision>
            <origin rpy="0 0 0" xyz="-0.009300 -0.00557 -0.08874" />
            <geometry>
                <box size="0.0414 0.0720 0.013" />
            </geometry>
        </collision>
    </link> <!--
    virtual link-->
    <link name="palm" />
    <joint name="palm_joint" type="fixed">
        <parent link="base_link" />
        <child link="palm" />
        <origin rpy="0.00000 -0.00000 0.00000" xyz="0 0 -0.065" />
    </joint> <!--  virtual link-->
    <link name="wrist" />
    <joint name="wrist_joint" type="fixed">
        <origin rpy="0 0 0" xyz="0 0 -0.03" />
        <parent link="palm" />
        <child link="wrist" />
    </joint>
    <link name="link_0.0">
        <visual>
            <geometry>
                <mesh filename="meshes/visual/link_0.0.obj" />
            </geometry>
        </visual>
        <collision>
            <geometry>
                <box size="0.0196 0.0275 0.0164" />
            </geometry>
            <origin rpy="0 0 0" xyz="0 0 0.0082" />
        </collision>
        <inertial>
            <mass value="0.0119" />
            <origin xyz="0 0 0" rpy="0 0 0" />
            <inertia ixx="1.01666658333e-06" ixy="0.0" ixz="0.0" iyy="6.47677333333e-07" iyz="0.0"
                izz="1.01666658333e-06" />
        </inertial>
    </link>
    <joint name="joint_0.0" type="revolute">
        <axis xyz="0 0 1" />
        <limit effort="10" lower="-0.47" upper="0.47" velocity="3.14" />
        <parent link="base_link" />
        <child link="link_0.0" />
        <origin rpy="-0.08726646255 0 0" xyz="0 0.0435 -0.001542" />
    </joint>
    <link name="link_1.0">
        <inertial>
            <mass value="0.065" />
            <origin xyz="0 0 0" rpy="0 0 0" />
 		<inertia ixx="1.01666658333e-06" ixy="0.0" ixz="0.0" iyy="6.47677333333e-07" iyz="0.0"
                izz="1.01666658333e-06" />
        </inertial>
        <visual>
            <geometry>
                <mesh filename="meshes/visual/link_1.0.obj" />
            </geometry>
        </visual>
        <collision>
            <geometry>
                <box size="0.0196 0.0275 0.054" />
            </geometry>
            <origin rpy="0 0 0" xyz="0 0 0.027" />
        </collision>
    </link>
    <joint name="joint_1.0" type="revolute">
        <limit effort="10" lower="-0.196" upper="1.61" velocity="3.14" />
        <axis xyz="0 1 0" />
        <parent link="link_0.0" />
        <child link="link_1.0" />
        <origin xyz="0 0 0.0164" />
    </joint>
    <link name="link_2.0">
        <inertial>
            <mass value="0.0355" />
            <origin xyz="0 0 0" rpy="0 0 0" />
		<inertia ixx="1.01666658333e-06" ixy="0.0" ixz="0.0" iyy="6.47677333333e-07" iyz="0.0"
                izz="1.01666658333e-06" />
        </inertial>
        <visual>
            <geometry>
                <mesh filename="meshes/visual/link_2.0.obj" />
            </geometry>
        </visual>
        <collision>
            <geometry>
                <box size="0.0196 0.0275 0.0384" />
            </geometry>
            <origin rpy="0 0 0" xyz="0 0 0.0192" />
        </collision>
    </link>
    <joint name="joint_2.0" type="revolute">
        <axis xyz="0 1 0" />
        <limit effort="10" lower="-0.174" upper="1.709" velocity="3.14" />
        <parent link="link_1.0" />
        <child link="link_2.0" />
        <origin xyz="0 0 0.054" />
    </joint>
    <link name="link_3.0">
        <visual>
            <geometry>
                <mesh filename="meshes/visual/link_3.0.obj" />
            </geometry>
        </visual>
        <collision>
            <geometry>
                <box size="0.0196 0.0269 0.022" />
            </geometry>
            <origin rpy="0 0 0" xyz="0 0 0.0047" />
        </collision>
        <inertial>
            <origin rpy="0 0 0" xyz="0 0 0.01335" />
            <mass value="0.02" />
            <inertia ixx="1e-5" ixy="0.0" ixz="0.0" iyy="2e-5" iyz="0.0" izz="2e-5" />
        </inertial>
    </link>
    <joint name="joint_3.0" type="revolute">
        <axis xyz="0 1 0" />
        <limit effort="10" lower="-0.227" upper="1.618" velocity="3.14" />
        <parent link="link_2.0" />
        <child link="link_3.0" />
        <origin xyz="0 0 0.0384" />
    </joint>
    <link name="link_3.0_tip">
        <inertial>
            <mass value="0.0168" />
            <origin xyz="0 0 0" rpy="0 0 0" />
            <inertia ixx="9.68e-07" ixy="0" ixz="0" iyy="9.68e-07" iyz="0" izz="9.68e-07" />
        </inertial>
        <visual>
            <geometry>
                <mesh filename="meshes/visual/link_tip.obj" />
            </geometry>
        </visual>
        <collision>
            <geometry>
                <mesh filename="meshes/collision/link_tip.obj" />
            </geometry>
        </collision>
    </link>
    <joint name="joint_3.0_tip" type="fixed">
        <parent link="link_3.0" />
        <child link="link_3.0_tip" />
        <origin rpy="0 0 0" xyz="0 0 0.0267" />
    </joint>
    <link name="link_4.0">
        <inertial>
            <mass value="0.005" />
            <origin xyz="0 0 0" />
            <inertia ixx="5.1458e-05" iyy="5.1458e-05" izz="6.125e-05" ixy="0" ixz="0" iyz="0" />
        </inertial>
        <visual>
            <geometry>
                <mesh filename="meshes/visual/link_0.0.obj" />
            </geometry>
        </visual>
        <collision>
            <geometry>
                <box size="0.0196 0.0275 0.0164" />
            </geometry>
            <origin rpy="0 0 0" xyz="0 0 0.0082" />
        </collision>
    </link>
    <joint name="joint_4.0" type="revolute">
        <axis xyz="0 0 1" />
        <limit effort="10" lower="-0.47" upper="0.47" velocity="3.14" />
        <parent link="base_link" />
        <child link="link_4.0" />
        <origin rpy="0.0 0 0" xyz="0 0 0.0007" />
    </joint>
    <link name="link_5.0">
        <inertial>
            <mass value="0.065" />
            <origin xyz="0 0 0" rpy="0 0 0" />
		<inertia ixx="1.01666658333e-06" ixy="0.0" ixz="0.0" iyy="6.47677333333e-07" iyz="0.0"
                izz="1.01666658333e-06" />
        </inertial>
        <visual>
            <geometry>
                <mesh filename="meshes/visual/link_1.0.obj" />
            </geometry>
        </visual>
        <collision>
            <geometry>
                <box size="0.0196 0.0275 0.054" />
            </geometry>
            <origin rpy="0 0 0" xyz="0 0 0.027" />
        </collision>
    </link>
    <joint name="joint_5.0" type="revolute">
        <limit effort="10" lower="-0.196" upper="1.61" velocity="3.14" />
        <axis xyz="0 1 0" />
        <parent link="link_4.0" />
        <child link="link_5.0" />
        <origin xyz="0 0 0.0164" />
    </joint>
    <link name="link_6.0">
        <inertial>
            <mass value="0.0355" />
            <origin xyz="0 0 0" rpy="0 0 0" />
           <inertia ixx="1.01666658333e-06" ixy="0.0" ixz="0.0" iyy="6.47677333333e-07" iyz="0.0"
                izz="1.01666658333e-06" />
        </inertial>
        <visual>
            <geometry>
                <mesh filename="meshes/visual/link_2.0.obj" />
            </geometry>
        </visual>
        <collision>
            <geometry>
                <box size="0.0196 0.0275 0.0384" />
            </geometry>
            <origin rpy="0 0 0" xyz="0 0 0.0192" />
        </collision>
    </link>
    <joint name="joint_6.0" type="revolute">
        <axis xyz="0 1 0" />
        <limit effort="10" lower="-0.174" upper="1.709" velocity="3.14" />
        <parent link="link_5.0" />
        <child link="link_6.0" />
        <origin xyz="0 0 0.054" />
    </joint>
    <link name="link_7.0">
        <inertial>
            <mass value="0.0388" />
            <origin xyz="0 0 0" rpy="0 0 0" />
          <inertia ixx="1.01666658333e-06" ixy="0.0" ixz="0.0" iyy="6.47677333333e-07" iyz="0.0"
                izz="1.01666658333e-06" />
        </inertial>
        <visual>
            <geometry>
                <mesh filename="meshes/visual/link_3.0.obj" />
            </geometry>
        </visual>
        <collision>
            <geometry>
                <box size="0.0196 0.0269 0.022" />
            </geometry>
            <origin rpy="0 0 0" xyz="0 0 0.0047" />
        </collision>
    </link>
    <joint name="joint_7.0" type="revolute">
        <axis xyz="0 1 0" />
        <limit effort="10" lower="-0.227" upper="1.618" velocity="3.14" />
        <parent link="link_6.0" />
        <child link="link_7.0" />
        <origin xyz="0 0 0.0384" />
    </joint>
    <link name="link_7.0_tip">
        <inertial>
            <mass value="0.0096" />
            <origin xyz="0 0 0" rpy="0 0 0" />
           <inertia ixx="1.01666658333e-06" ixy="0.0" ixz="0.0" iyy="6.47677333333e-07" iyz="0.0"
                izz="1.01666658333e-06" />
        </inertial>
        <visual>
            <geometry>
                <mesh filename="meshes/visual/link_tip.obj" />
            </geometry>
        </visual>
        <collision>
            <geometry>
                <mesh filename="meshes/collision/link_tip.obj" />
            </geometry>
        </collision>
    </link>
    <joint name="joint_7.0_tip" type="fixed">
        <parent link="link_7.0" />
        <child link="link_7.0_tip" />
        <origin rpy="0 0 0" xyz="0 0 0.0267" />
    </joint>
    <link name="link_8.0">
        <inertial>
            <mass value="0.005" />
            <origin xyz="0 0 0" />
            <inertia ixx="5.1458e-05" iyy="5.1458e-05" izz="6.125e-05" ixy="0" ixz="0" iyz="0" />
        </inertial>
        <visual>
            <geometry>
                <mesh filename="meshes/visual/link_0.0.obj" />
            </geometry>
        </visual>
        <collision>
            <geometry>
                <box size="0.0196 0.0275 0.0164" />
            </geometry>
            <origin rpy="0 0 0" xyz="0 0 0.0082" />
        </collision>
    </link>
    <joint name="joint_8.0" type="revolute">
        <axis xyz="0 0 1" />
        <limit effort="10" lower="-0.47" upper="0.47" velocity="3.14" />
        <parent link="base_link" />
        <child link="link_8.0" />
        <origin rpy="0.08726646255 0 0" xyz="0 -0.0435 -0.001542" />
    </joint>
    <link name="link_9.0">
        <inertial>
            <mass value="0.065" />
            <origin xyz="0 0 0" rpy="0 0 0" />
            <inertia ixx="1.01666658333e-06" ixy="0.0" ixz="0.0" iyy="6.47677333333e-07" iyz="0.0"
                izz="1.01666658333e-06" />
        </inertial>
        <visual>
            <geometry>
                <mesh filename="meshes/visual/link_1.0.obj" />
            </geometry>
        </visual>
        <collision>
            <geometry>
                <box size="0.0196 0.0275 0.054" />
            </geometry>
            <origin rpy="0 0 0" xyz="0 0 0.027" />
        </collision>
    </link>
    <joint name="joint_9.0" type="revolute">
        <limit effort="10" lower="-0.196" upper="1.61" velocity="3.14" />
        <axis xyz="0 1 0" />
        <parent link="link_8.0" />
        <child link="link_9.0" />
        <origin xyz="0 0 0.0164" />
    </joint>
    <link name="link_10.0">
        <inertial>
            <mass value="0.0355" />
            <origin xyz="0 0 0" rpy="0 0 0" />
          <inertia ixx="1.01666658333e-06" ixy="0.0" ixz="0.0" iyy="6.47677333333e-07" iyz="0.0"
                izz="1.01666658333e-06" />
        </inertial>
        <visual>
            <geometry>
                <mesh filename="meshes/visual/link_2.0.obj" />
            </geometry>
        </visual>
        <collision>
            <geometry>
                <box size="0.0196 0.0275 0.0384" />
            </geometry>
            <origin rpy="0 0 0" xyz="0 0 0.0192" />
        </collision>
    </link>
    <joint name="joint_10.0" type="revolute">
        <axis xyz="0 1 0" />
        <limit effort="10" lower="-0.174" upper="1.709" velocity="3.14" />
        <parent link="link_9.0" />
        <child link="link_10.0" />
        <origin xyz="0 0 0.054" />
    </joint>
    <link name="link_11.0">
        <inertial>
            <mass value="0.0096" />
            <origin xyz="0 0 0" rpy="0 0 0" />
           <inertia ixx="1.01666658333e-06" ixy="0.0" ixz="0.0" iyy="6.47677333333e-07" iyz="0.0"
                izz="1.01666658333e-06" />
        </inertial>
        <visual>
            <geometry>
                <mesh filename="meshes/visual/link_3.0.obj" />
            </geometry>
        </visual>
        <collision>
            <geometry>
                <box size="0.0196 0.0269 0.022" />
            </geometry>
            <origin rpy="0 0 0" xyz="0 0 0.0047" />
        </collision>
    </link>
    <joint name="joint_11.0" type="revolute">
        <axis xyz="0 1 0" />
        <limit effort="10" lower="-0.227" upper="1.618" velocity="3.14" />
        <parent link="link_10.0" />
        <child link="link_11.0" />
        <origin xyz="0 0 0.0384" />
    </joint>
    <link name="link_11.0_tip">
        <inertial>
            <mass value="0.0168" />
            <origin xyz="0 0 0" rpy="0 0 0" />
            <inertia ixx="9.68e-07" ixy="0" ixz="0" iyy="9.68e-07" iyz="0" izz="9.68e-07" />
        </inertial>
        <visual>
            <geometry>
                <mesh filename="meshes/visual/link_tip.obj" />
            </geometry>
        </visual>
        <collision>
            <geometry>
                <mesh filename="meshes/collision/link_tip.obj" />
            </geometry>
        </collision>
    </link>
    <joint name="joint_11.0_tip" type="fixed">
        <parent link="link_11.0" />
        <child link="link_11.0_tip" />
        <origin rpy="0 0 0" xyz="0 0 0.0267" />
    </joint> <!-- THUMB -->
    <link name="link_12.0">
        <inertial>
            <mass value="0.0176" />
            <origin xyz="0 0 0" rpy="0 0 0" />
           <inertia ixx="1.01666658333e-06" ixy="0.0" ixz="0.0" iyy="6.47677333333e-07" iyz="0.0"
                izz="1.01666658333e-06" />
        </inertial>
        <visual>
            <geometry>
                <mesh filename="meshes/visual/link_12.0_right.obj" />
            </geometry>
        </visual>
        <collision>
            <geometry>
                <box size="0.0358 0.034 0.0455" />
            </geometry>
            <origin rpy="0 0 0" xyz="-0.0179 0.009 0.0145" />
        </collision>
    </link>
    <joint name="joint_12.0" type="revolute">
        <axis xyz="-1 0 0" />
        <limit effort="10" lower="0.263" upper="1.396" velocity="3.14" />
        <parent link="base_link" />
        <child link="link_12.0" />
        <origin rpy="0 -1.65806278845 -1.5707963259" xyz="-0.0182 0.019333 -0.045987" />
    </joint>
    <link name="link_13.0">
        <inertial>
            <mass value="0.0119" />
            <origin xyz="0 0 0" rpy="0 0 0" />
            <inertia ixx="1.01666658333e-06" ixy="0.0" ixz="0.0" iyy="6.47677333333e-07" iyz="0.0"
                izz="1.01666658333e-06" />
        </inertial>
        <visual>
            <geometry>
                <mesh filename="meshes/visual/link_13.0.obj" />
            </geometry>
        </visual>
        <collision>
            <geometry>
                <box size="0.0196 0.0275 0.0177" />
            </geometry>
            <origin rpy="0 0 0" xyz="0 0 0.00885" />
        </collision>
    </link>
    <joint name="joint_13.0" type="revolute">
        <axis xyz="0 0 1" />
        <limit effort="10" lower="-0.105" upper="1.163" velocity="3.14" />
        <parent link="link_12.0" />
        <child link="link_13.0" />
        <origin xyz="-0.027 0.005 0.0399" />
    </joint>
    <link name="link_14.0">
        <inertial>
            <mass value="0.038" />
            <origin xyz="0 0 0" rpy="0 0 0" />
          <inertia ixx="1.01666658333e-06" ixy="0.0" ixz="0.0" iyy="6.47677333333e-07" iyz="0.0"
                izz="1.01666658333e-06" />
        </inertial>
        <visual>
            <geometry>
                <mesh filename="meshes/visual/link_14.0.obj" />
            </geometry>
        </visual>
        <collision>
            <geometry>
                <box size="0.0196 0.0275 0.0514" />
            </geometry>
            <origin rpy="0 0 0" xyz="0 0 0.0257" />
        </collision>
    </link>
    <joint name="joint_14.0" type="revolute">
        <axis xyz="0 1 0" />
        <limit effort="10" lower="-0.189" upper="1.644" velocity="3.14" />
        <parent link="link_13.0" />
        <child link="link_14.0" />
        <origin xyz="0 0 0.0177" />
    </joint>
    <link name="link_15.0">
        <inertial>
            <mass value="0.0388" />
            <origin xyz="0 0 0" rpy="0 0 0" />
          <inertia ixx="1.01666658333e-06" ixy="0.0" ixz="0.0" iyy="6.47677333333e-07" iyz="0.0"
                izz="1.01666658333e-06" />
        </inertial>
        <visual>
            <geometry>
                <mesh filename="meshes/visual/link_15.0.obj" />
            </geometry>
        </visual>
        <collision>
            <geometry>
                <box size="0.0196 0.0269 0.04" />
            </geometry>
            <origin rpy="0 0 0" xyz="0 0 0.01125" />
        </collision>
    </link>
    <joint name="joint_15.0" type="revolute">
        <axis xyz="0 1 0" />
        <limit effort="10" lower="-0.162" upper="1.719" velocity="3.14" />
        <parent link="link_14.0" />
        <child link="link_15.0" />
        <origin xyz="0 0 0.0514" />
    </joint>
    <link name="link_15.0_tip">
        <inertial>
            <mass value="0.0168" />
            <origin xyz="0 0 0" rpy="0 0 0" />
            <inertia ixx="1.01666658333e-06" ixy="0.0" ixz="0.0" iyy="6.47677333333e-07" iyz="0.0"
                izz="1.01666658333e-06" />
        </inertial>
        <visual>
            <geometry>
                <mesh filename="meshes/visual/link_tip.obj" />
            </geometry>
        </visual>
        <collision>
            <geometry>
                <mesh filename="meshes/collision/link_tip.obj" />
            </geometry>
        </collision>
    </link>
    <joint name="joint_15.0_tip" type="fixed">
        <parent link="link_15.0" />
        <child link="link_15.0_tip" />
        <origin rpy="0 0 0" xyz="0 0 0.0423" />
    </joint>

</robot>
