
<mujoco model="franka_allegro">
  <compiler angle="radian" meshdir="assets" autolimits="true"/>
  <option integrator="implicitfast"/>

  <default>
    <default class="panda">
      <material specular="0.5" shininess="0.25"/>
      <joint armature="0.1" damping="1" axis="0 0 1" range="-2.8973 2.8973"/>
      <general dyntype="none" biastype="affine" ctrlrange="-2.8973 2.8973" forcerange="-87 87"/>

      <default class="finger">
        <joint axis="0 1 0" type="slide" range="0 0.04"/>
      </default>

      <default class="panda/visual">
        <geom type="mesh" contype="0" conaffinity="0" group="2"/>
      </default>

      <default class="panda/collision">
        <geom type="mesh" group="3"/>
      </default>

      <site size="0.001" rgba="0.5 0.5 0.5 0.3" group="4"/>
    </default>

    <default class="allegro_right">
      <joint axis="0 1 0" damping=".1"/>
      <position kp="1"/>
      <geom density="800"/>

      <default class="visual">
        <geom type="mesh" contype="0" conaffinity="0" group="2" material="black"/>
        <default class="palm_visual">
          <geom mesh="base_link"/>
        </default>
        <default class="base_visual">
          <geom mesh="link_0.0"/>
        </default>
        <default class="proximal_visual">
          <geom mesh="link_1.0"/>
        </default>
        <default class="medial_visual">
          <geom mesh="link_2.0"/>
        </default>
        <default class="distal_visual">
          <geom mesh="link_3.0"/>
        </default>
        <default class="fingertip_visual">
          <geom pos="0 0 0.0267" material="white" mesh="link_3.0_tip"/>
        </default>
        <default class="thumbtip_visual">
          <geom pos="0 0 0.0423" material="white" mesh="link_15.0_tip"/>
        </default>
      </default>

      <default class="collision">
        <geom group="3" type="box" mass="0.1"/>
        <default class="palm_collision">
          <geom size="0.0204 0.0565 0.0475" pos="-0.0093 0 -0.0475"/>
        </default>
        <default class="base_collision">
          <geom size="0.0098 0.01375 0.0082" pos="0 0 0.0082"/>
          <default class="thumb_base_collision">
            <geom size="0.0179 0.017 0.02275" pos="-0.0179 0.009 0.0145"/>
          </default>
        </default>
        <default class="proximal_collision">
          <geom size="0.0098 0.01375 0.027" pos="0 0 0.027"/>
          <default class="thumb_proximal_collision">
            <geom size="0.0098 0.01375 0.00885" pos="0 0 0.00885"/>
          </default>
        </default>
        <default class="medial_collision">
          <geom size="0.0098 0.01375 0.0192" pos="0 0 0.0192"/>
          <default class="thumb_medial_collision">
            <geom size="0.0098 0.01375 0.0257" pos="0 0 0.0257"/>
          </default>
        </default>
        <default class="distal_collision">
          <geom size="0.0098 0.01375 0.008" pos="0 0 0.008"/>
          <default class="thumb_distal_collision">
            <geom size="0.0098 0.01375 0.0157" pos="0 0 0.0157"/>
          </default>
        </default>
        <default class="fingertip_collision">
          <geom type="capsule" size="0.012 0.01" pos="0 0 0.019"/>
          <default class="thumbtip_collision">
            <geom type="capsule" size="0.012 0.008" pos="0 0 0.035"/>
          </default>
        </default>
      </default>

      <default class="base">
        <joint axis="0 0 1" range="-0.47 0.47"/>
        <position ctrlrange="-0.47 0.47"/>
      </default>
      <default class="proximal">
        <joint range="-0.196 1.61"/>
        <position ctrlrange="-0.196 1.61"/>
      </default>
      <default class="medial">
        <joint range="-0.174 1.709"/>
        <position ctrlrange="-0.174 1.709"/>
      </default>
      <default class="distal">
        <joint range="-0.227 1.618"/>
        <position ctrlrange="-0.227 1.618"/>
      </default>
      <default class="thumb_base">
        <joint axis="-1 0 0" range="0.263 1.396"/>
        <position ctrlrange="0.263 1.396"/>
      </default>
      <default class="thumb_proximal">
        <joint axis="0 0 1" range="-0.105 1.163"/>
        <position ctrlrange="-0.105 1.163"/>
      </default>
      <default class="thumb_medial">
        <joint range="-0.189 1.644"/>
        <position ctrlrange="-0.189 1.644"/>
      </default>
      <default class="thumb_distal">
        <joint range="-0.162 1.719"/>
        <position ctrlrange="-0.162 1.719"/>
      </default>
    </default>
  </default>

  <asset>
    <!-- Materials -->
    <material class="panda" name="white" rgba="1 1 1 1"/>
    <material class="panda" name="off_white" rgba="0.901961 0.921569 0.929412 1"/>
    <material class="panda" name="dark_grey" rgba="0.25 0.25 0.25 1"/>
    <material class="panda" name="green" rgba="0 1 0 1"/>
    <material class="panda" name="light_blue" rgba="0.039216 0.541176 0.780392 1"/>
    <material name="black" rgba="0.2 0.2 0.2 1"/>

    <!-- Collision meshes -->
    <mesh name="link0_c" file="link0.stl"/>
    <mesh name="link1_c" file="link1.stl"/>
    <mesh name="link2_c" file="link2.stl"/>
    <mesh name="link3_c" file="link3.stl"/>
    <mesh name="link4_c" file="link4.stl"/>
    <mesh name="link5_c0" file="link5_collision_0.obj"/>
    <mesh name="link5_c1" file="link5_collision_1.obj"/>
    <mesh name="link5_c2" file="link5_collision_2.obj"/>
    <mesh name="link6_c" file="link6.stl"/>
    <mesh name="link7_c" file="link7.stl"/>

    <!-- Visual meshes -->
    <mesh name="link0_0" file="link0_0.obj"/>
    <mesh name="link0_1" file="link0_1.obj"/>
    <mesh name="link0_2" file="link0_2.obj"/>
    <mesh name="link0_3" file="link0_3.obj"/>
    <mesh name="link0_4" file="link0_4.obj"/>
    <mesh name="link0_5" file="link0_5.obj"/>
    <mesh name="link0_7" file="link0_7.obj"/>
    <mesh name="link0_8" file="link0_8.obj"/>
    <mesh name="link0_9" file="link0_9.obj"/>
    <mesh name="link0_10" file="link0_10.obj"/>
    <mesh name="link0_11" file="link0_11.obj"/>
    <mesh name="link1" file="link1.obj"/>
    <mesh name="link2" file="link2.obj"/>
    <mesh name="link3_0" file="link3_0.obj"/>
    <mesh name="link3_1" file="link3_1.obj"/>
    <mesh name="link3_2" file="link3_2.obj"/>
    <mesh name="link3_3" file="link3_3.obj"/>
    <mesh name="link4_0" file="link4_0.obj"/>
    <mesh name="link4_1" file="link4_1.obj"/>
    <mesh name="link4_2" file="link4_2.obj"/>
    <mesh name="link4_3" file="link4_3.obj"/>
    <mesh name="link5_0" file="link5_0.obj"/>
    <mesh name="link5_1" file="link5_1.obj"/>
    <mesh name="link5_2" file="link5_2.obj"/>
    <mesh name="link6_0" file="link6_0.obj"/>
    <mesh name="link6_1" file="link6_1.obj"/>
    <mesh name="link6_2" file="link6_2.obj"/>
    <mesh name="link6_3" file="link6_3.obj"/>
    <mesh name="link6_4" file="link6_4.obj"/>
    <mesh name="link6_5" file="link6_5.obj"/>
    <mesh name="link6_6" file="link6_6.obj"/>
    <mesh name="link6_7" file="link6_7.obj"/>
    <mesh name="link6_8" file="link6_8.obj"/>
    <mesh name="link6_9" file="link6_9.obj"/>
    <mesh name="link6_10" file="link6_10.obj"/>
    <mesh name="link6_11" file="link6_11.obj"/>
    <mesh name="link6_12" file="link6_12.obj"/>
    <mesh name="link6_13" file="link6_13.obj"/>
    <mesh name="link6_14" file="link6_14.obj"/>
    <mesh name="link6_15" file="link6_15.obj"/>
    <mesh name="link6_16" file="link6_16.obj"/>
    <mesh name="link7_0" file="link7_0.obj"/>
    <mesh name="link7_1" file="link7_1.obj"/>
    <mesh name="link7_2" file="link7_2.obj"/>
    <mesh name="link7_3" file="link7_3.obj"/>
    <mesh name="link7_4" file="link7_4.obj"/>
    <mesh name="link7_5" file="link7_5.obj"/>
    <mesh name="link7_6" file="link7_6.obj"/>
    <mesh name="link7_7" file="link7_7.obj"/>

    <!-- Allegro hand meshes -->
    <mesh file="base_link.stl" name="base_link"/>
    <mesh file="hand_link_0.0.stl" name="link_0.0"/>
    <mesh file="hand_link_1.0.stl" name="link_1.0"/>
    <mesh file="hand_link_2.0.stl" name="link_2.0"/>
    <mesh file="hand_link_3.0.stl" name="link_3.0"/>
    <mesh file="hand_link_3.0_tip.stl" name="link_3.0_tip"/>
    <mesh file="hand_link_12.0_right.stl" name="link_12.0_right"/>
    <mesh file="hand_link_13.0.stl" name="link_13.0"/>
    <mesh file="hand_link_14.0.stl" name="link_14.0"/>
    <mesh file="hand_link_15.0.stl" name="link_15.0"/>
    <mesh file="hand_link_15.0_tip.stl" name="link_15.0_tip"/>
  </asset>

  <worldbody>
    <!-- Franka robot up to link7 -->
    <body name="link0" pos='0 0 0.05' childclass="panda">
      <inertial mass="0.629769" pos="-0.041018 -0.00014 0.049974"
                fullinertia="0.00315 0.00388 0.004285 8.2904e-7 0.00015 8.2299e-6"/>
      <geom mesh="link0_0" material="off_white" class="panda/visual"/>
      <geom mesh="link0_1" material="dark_grey" class="panda/visual"/>
      <geom mesh="link0_2" material="off_white" class="panda/visual"/>
      <geom mesh="link0_3" material="dark_grey" class="panda/visual"/>
      <geom mesh="link0_4" material="off_white" class="panda/visual"/>
      <geom mesh="link0_5" material="dark_grey" class="panda/visual"/>
      <geom mesh="link0_7" material="white" class="panda/visual"/>
      <geom mesh="link0_8" material="white" class="panda/visual"/>
      <geom mesh="link0_9" material="dark_grey" class="panda/visual"/>
      <geom mesh="link0_10" material="off_white" class="panda/visual"/>
      <geom mesh="link0_11" material="white" class="panda/visual"/>
      <geom mesh="link0_c" class="panda/collision"/>

      <body name="link1" pos="0 0 0.333">
        <inertial mass="4.970684" pos="0.003875 0.002081 -0.04762"
                  fullinertia="0.70337 0.70661 0.0091170 -0.00013900 0.0067720 0.019169"/>
        <joint name="joint1"/>
        <geom material="white" mesh="link1" class="panda/visual"/>
        <geom mesh="link1_c" class="panda/collision"/>

        <body name="link2" quat="1 -1 0 0">
          <inertial mass="0.646926" pos="-0.003141 -0.02872 0.003495"
                    fullinertia="0.0079620 2.8110e-2 2.5995e-2 -3.925e-3 1.0254e-2 7.04e-4"/>
          <joint name="joint2" range="-1.7628 1.7628"/>
          <geom material="white" mesh="link2" class="panda/visual"/>
          <geom mesh="link2_c" class="panda/collision"/>

          <body name="link3" pos="0 -0.316 0" quat="1 1 0 0">
            <joint name="joint3"/>
            <inertial mass="3.228604" pos="2.7518e-2 3.9252e-2 -6.6502e-2"
                      fullinertia="3.7242e-2 3.6155e-2 1.083e-2 -4.761e-3 -1.1396e-2 -1.2805e-2"/>
            <geom mesh="link3_0" material="white" class="panda/visual"/>
            <geom mesh="link3_1" material="white" class="panda/visual"/>
            <geom mesh="link3_2" material="white" class="panda/visual"/>
            <geom mesh="link3_3" material="dark_grey" class="panda/visual"/>
            <geom mesh="link3_c" class="panda/collision"/>

            <body name="link4" pos="0.0825 0 0" quat="1 1 0 0">
              <inertial mass="3.587895" pos="-5.317e-2 1.04419e-1 2.7454e-2"
                        fullinertia="2.5853e-2 1.9552e-2 2.8323e-2 7.796e-3 -1.332e-3 8.641e-3"/>
              <joint name="joint4" range="-3.0718 -0.0698"/>
              <geom mesh="link4_0" material="white" class="panda/visual"/>
              <geom mesh="link4_1" material="white" class="panda/visual"/>
              <geom mesh="link4_2" material="dark_grey" class="panda/visual"/>
              <geom mesh="link4_3" material="white" class="panda/visual"/>
              <geom mesh="link4_c" class="panda/collision"/>

              <body name="link5" pos="-0.0825 0.384 0" quat="1 -1 0 0">
                <inertial mass="1.225946" pos="-1.1953e-2 4.1065e-2 -3.8437e-2"
                          fullinertia="3.5549e-2 2.9474e-2 8.627e-3 -2.117e-3 -4.037e-3 2.29e-4"/>
                <joint name="joint5"/>
                <geom mesh="link5_0" material="dark_grey" class="panda/visual"/>
                <geom mesh="link5_1" material="white" class="panda/visual"/>
                <geom mesh="link5_2" material="white" class="panda/visual"/>
                <geom mesh="link5_c0" class="panda/collision"/>
                <geom mesh="link5_c1" class="panda/collision"/>
                <geom mesh="link5_c2" class="panda/collision"/>

                <body name="link6" quat="1 1 0 0">
                  <inertial mass="1.666555" pos="6.0149e-2 -1.4117e-2 -1.0517e-2"
                            fullinertia="1.964e-3 4.354e-3 5.433e-3 1.09e-4 -1.158e-3 3.41e-4"/>
                  <joint name="joint6" range="-0.0175 3.7525"/>
                  <geom mesh="link6_0" material="off_white" class="panda/visual"/>
                  <geom mesh="link6_1" material="white" class="panda/visual"/>
                  <geom mesh="link6_2" material="dark_grey" class="panda/visual"/>
                  <geom mesh="link6_3" material="white" class="panda/visual"/>
                  <geom mesh="link6_4" material="white" class="panda/visual"/>
                  <geom mesh="link6_5" material="white" class="panda/visual"/>
                  <geom mesh="link6_6" material="white" class="panda/visual"/>
                  <geom mesh="link6_7" material="light_blue" class="panda/visual"/>
                  <geom mesh="link6_8" material="light_blue" class="panda/visual"/>
                  <geom mesh="link6_9" material="dark_grey" class="panda/visual"/>
                  <geom mesh="link6_10" material="dark_grey" class="panda/visual"/>
                  <geom mesh="link6_11" material="white" class="panda/visual"/>
                  <geom mesh="link6_12" material="green" class="panda/visual"/>
                  <geom mesh="link6_13" material="white" class="panda/visual"/>
                  <geom mesh="link6_14" material="dark_grey" class="panda/visual"/>
                  <geom mesh="link6_15" material="dark_grey" class="panda/visual"/>
                  <geom mesh="link6_16" material="white" class="panda/visual"/>
                  <geom mesh="link6_c" class="panda/collision"/>

                  <!-- Merge the two link7 blocks into one. Keep inertial, joint, geoms, then attach the Allegro hand. -->
                  <body name="link7" pos="0.088 0 0" quat="1 1 0 0">
                    <inertial mass="0.735522" 
                              pos="0.010517 -0.004252 0.061597"
                              fullinertia="0.012516 0.010027 0.004815 -0.000428 -0.001196 -0.000741"/>
                    <joint name="joint7"/>
                    <geom mesh="link7_0" material="white" class="panda/visual"/>
                    <geom mesh="link7_1" material="dark_grey" class="panda/visual"/>
                    <geom mesh="link7_2" material="dark_grey" class="panda/visual"/>
                    <geom mesh="link7_3" material="dark_grey" class="panda/visual"/>
                    <geom mesh="link7_4" material="dark_grey" class="panda/visual"/>
                    <geom mesh="link7_5" material="dark_grey" class="panda/visual"/>
                    <geom mesh="link7_6" material="dark_grey" class="panda/visual"/>
                    <geom mesh="link7_7" material="white" class="panda/visual"/>
                    <geom mesh="link7_c" class="panda/collision"/>

                    <!-- Allegro Right Hand as a child of link7 -->
                    <!-- Updated 'pos' to 0.007 (was 0.107) and 'quat' to new combined rotation -->
                    <!-- pos="0.05 0.0 0.14" -->
                    <body name="allegro_hand"
                    
                      
                          pos="0.15 0.0 0.14"
                          quat="-0.27328151 -0.65059802 0.27328151 -0.65059802"
                          childclass="allegro_right">
                      <geom class="palm_visual" mesh="base_link"/>
                      <geom class="palm_collision"/>

                      <!-- FF Finger -->
                      <body name="ff_base" pos="0 0.0435 -0.001542" quat="0.999048 -0.0436194 0 0">
                        <joint name="ffj0" class="base" />
                        <geom class="base_visual" />
                        <geom class="base_collision" />
                        <body name="ff_proximal" pos="0 0 0.0164">
                          <joint name="ffj1" class="proximal" />
                          <geom class="proximal_visual" />
                          <geom class="proximal_collision" />
                          <body name="ff_medial" pos="0 0 0.054">
                            <joint name="ffj2" class="medial" />
                            <geom class="medial_visual" />
                            <geom class="medial_collision" />
                            <body name="ff_distal" pos="0 0 0.0384">
                              <joint name="ffj3" class="distal" />
                              <geom class="distal_visual" />
                              <geom class="distal_collision" />
                              <body name="ff_tip">
                                <geom class="fingertip_visual" />
                                <geom class="fingertip_collision" />
                              </body>
                            </body>
                          </body>
                        </body>
                      </body>

                      <!-- MF Finger -->
                      <body name="mf_base" pos="0 0 0.0007">
                        <joint name="mfj0" class="base" />
                        <geom class="base_visual" />
                        <geom class="base_collision" />
                        <body name="mf_proximal" pos="0 0 0.0164">
                          <joint name="mfj1" class="proximal" />
                          <geom class="proximal_visual" />
                          <geom class="proximal_collision" />
                          <body name="mf_medial" pos="0 0 0.054">
                            <joint name="mfj2" class="medial" />
                            <geom class="medial_visual" />
                            <geom class="medial_collision" />
                            <body name="mf_distal" pos="0 0 0.0384">
                              <joint name="mfj3" class="distal" />
                              <geom class="distal_visual" />
                              <geom class="distal_collision" />
                              <body name="mf_tip">
                                <geom class="fingertip_visual" />
                                <geom class="fingertip_collision" />
                              </body>
                            </body>
                          </body>
                        </body>
                      </body>

                      <!-- RF Finger -->
                      <body name="rf_base" pos="0 -0.0435 -0.001542" quat="0.999048 0.0436194 0 0">
                        <joint name="rfj0" class="base" />
                        <geom class="base_visual" />
                        <geom class="base_collision" />
                        <body name="rf_proximal" pos="0 0 0.0164">
                          <joint name="rfj1" class="proximal" />
                          <geom class="proximal_visual" />
                          <geom class="proximal_collision" />
                          <body name="rf_medial" pos="0 0 0.054">
                            <joint name="rfj2" class="medial" />
                            <geom class="medial_visual" />
                            <geom class="medial_collision" />
                            <body name="rf_distal" pos="0 0 0.0384">
                              <joint name="rfj3" class="distal" />
                              <geom class="distal_visual" />
                              <geom class="distal_collision" />
                              <body name="rf_tip">
                                <geom class="fingertip_visual" />
                                <geom class="fingertip_collision" />
                              </body>
                            </body>
                          </body>
                        </body>
                      </body>

                      <!-- Thumb Finger -->
                      <body name="th_base" pos="-0.0182 0.019333 -0.045987" quat="0.477714 -0.521334 -0.521334 -0.477714">
                        <joint name="thj0" class="thumb_base" />
                        <geom class="visual" mesh="link_12.0_right" />
                        <geom class="thumb_base_collision" />
                        <body name="th_proximal" pos="-0.027 0.005 0.0399">
                          <joint name="thj1" class="thumb_proximal" />
                          <geom class="visual" mesh="link_13.0" />
                          <geom class="thumb_proximal_collision" />
                          <body name="th_medial" pos="0 0 0.0177">
                            <joint name="thj2" class="thumb_medial" />
                            <geom class="visual" mesh="link_14.0" />
                            <geom class="thumb_medial_collision" />
                            <body name="th_distal" pos="0 0 0.0514">
                              <joint name="thj3" class="thumb_distal" />
                              <geom class="visual" mesh="link_15.0" />
                              <geom class="thumb_distal_collision" />
                              <body name="th_tip">
                                <geom class="thumbtip_visual" />
                                <geom class="thumbtip_collision" />
                              </body>
                            </body>
                          </body>
                        </body>
                      </body>
                    </body><!-- /allegro_hand -->

                  </body><!-- /link7 -->
                </body><!-- /link6 -->
              </body><!-- /link5 -->
            </body><!-- /link4 -->
          </body><!-- /link3 -->
        </body><!-- /link2 -->
      </body><!-- /link1 -->
    </body><!-- /link0 -->
  </worldbody>

  <actuator>
    <general class="panda" name="actuator1" joint="joint1" gainprm="4500" biasprm="0 -4500 -450"/>
    <general class="panda" name="actuator2" joint="joint2" gainprm="4500" biasprm="0 -4500 -450"
      ctrlrange="-1.7628 1.7628"/>
    <general class="panda" name="actuator3" joint="joint3" gainprm="3500" biasprm="0 -3500 -350"/>
    <general class="panda" name="actuator4" joint="joint4" gainprm="3500" biasprm="0 -3500 -350"
      ctrlrange="-3.0718 -0.0698"/>
    <general class="panda" name="actuator5" joint="joint5" gainprm="2000" biasprm="0 -2000 -200" forcerange="-12 12"/>
    <general class="panda" name="actuator6" joint="joint6" gainprm="2000" biasprm="0 -2000 -200" forcerange="-12 12"
      ctrlrange="-0.0175 3.7525"/>
    <general class="panda" name="actuator7" joint="joint7" gainprm="2000" biasprm="0 -2000 -200" forcerange="-12 12"/>

    <position name="ffa0" joint="ffj0" class="base" />
    <position name="ffa1" joint="ffj1" class="proximal" />
    <position name="ffa2" joint="ffj2" class="medial" />
    <position name="ffa3" joint="ffj3" class="distal" />

    <position name="mfa0" joint="mfj0" class="base" />
    <position name="mfa1" joint="mfj1" class="proximal" />
    <position name="mfa2" joint="mfj2" class="medial" />
    <position name="mfa3" joint="mfj3" class="distal" />

    <position name="rfa0" joint="rfj0" class="base" />
    <position name="rfa1" joint="rfj1" class="proximal" />
    <position name="rfa2" joint="rfj2" class="medial" />
    <position name="rfa3" joint="rfj3" class="distal" />

    <position name="tha0" joint="thj0" class="thumb_base" />
    <position name="tha1" joint="thj1" class="thumb_proximal" />
    <position name="tha2" joint="thj2" class="thumb_medial" />
    <position name="tha3" joint="thj3" class="thumb_distal" />
  </actuator>
  


</mujoco>

